Workbook

Sheet Raw_Data
A1: Booking ID | B1: Hotel | C1: Customer_Name | D1: Country | E1: Arrival Date | F1: Lead_Time Days | G1: Market Segment | H1: Room Type | I1: ADR | J1: Total Nights | K1: Is Canceled | L1: Booking Channel
A2: 100027 | B2: RESORT HOTEL | C2: Lucas Garcia | D2: UNITED KINGDOM | E2: 9253 | F2: 119 | G2: Direct | H2: E | I2: N/A | J2: 7 | K2: No | L2: expedia
A3: 100025 | B3: resort hotel | C3: AVA MARTINEZ | D3: USA | E3: 2025-05-22 | F3: 4 | G3: Online TA | H3: D | I3: $95.28 | J3: 8 | K3: Yes | L3: Direct Website
A4: 100037 | B4: city hotel | C4: Anna Muller | D4: Brazil | E4: 2025-03-14 | F4: 43 | G4: direct | H4: A | I4: 283.01 | J4: 6 | K4: no | L4: Travel Agent
A5: 100028 | B5: City Hotel | C5: Ethan Davis | D5: united kingdom | E5: 9273 | F5: 44 | G5: online ta | H5: D | I5: 273.81 | J5: 2 | K5: FALSE | L5: direct website
A6: 100023 | B6: RESORT HOTEL | C6: Olivia Brown | D6: BRAZIL | E6: 2025-01-23 | F6: 37 | G6: offline ta/to | H6: C | I6: $147.32 | J6: 9 | K6: yes | L6: Expedia
A7: 100042 | B7: City Hotel | C7: Mia Wilson | D7: USA | E7: 2025-06-13 | F7: 84 | G7: Online TA | H7: C | I7: $281.61 | J7: 9 | K7: No | L7: direct website
A8: 100039 | B8: Resort Hotel | C8: henry harris | D8: Ireland | E8: 01/08/2025 | F8: 108 | G8: online ta | H8: D | I8: 306.24 | J8: 3 | K8: NO | L8: Direct Website
A9: 100003 | B9: RESORT HOTEL | C9: maria silva | D9: Spain | E9: 9194 | F9: thirty | G9: Offline TA/TO | H9: A | I9: 158.83 | J9: 8 | K9: FALSE | L9: direct website
A10: 100014 | B10: resort hotel | C10: Henry Harris | D10: GERMANY | E10: 2025-06-04 | F10: 113 | G10: offline ta/to | H10: C | I10: 90.01 | J10: 2 | K10: No | L10: Expedia
A11: 100007 | B11: RESORT HOTEL | C11: alexander thompson | E11: 9223 | F11: 15 | G11: DIRECT | H11: C | I11: 122.26 | J11: 4 | K11: 0 | L11: Booking.com
A12: 100043 | B12: resort hotel | C12: LIAM O'BRIEN | D12: Brazil | E12: 02/23/2025 | F12: -39 | G12: Online TA | H12: A | J12: 1 | K12: FALSE | L12: Direct Website
A13: 100020 | B13: City Hotel | C13: amelia martin | D13: USA | E13: 06/11/2025 | F13: 60 | G13: CORPORATE | H13: D | J13: 9 | K13: NO | L13: EXPEDIA
A14: 100041 | B14: RESORT HOTEL | C14: James Anderson | D14: PORTUGAL | E14: 9215 | F14: thirty | G14: Corporate | H14: D | I14: N/A | J14: 3 | K14: NO | L14: BOOKING.COM
A15: 100002 | B15: Resort Hotel | C15: James Anderson | D15: Italy | E15: 9196 | F15: 28 | G15: Direct | H15: A | I15: 84.11 | J15: 2 | K15: 0 | L15: a
A16: 100034 | B16: resort hotel | C16: Emma Johnson | D16: SPAIN | E16: 9213 | F16: 11 | G16: offline ta/to | H16: B | I16: 105.19 | J16: 2 | K16: yes | L16: Travel Agent
A17: 100029 | B17: city hotel | C17: mia wilson | D17: spain | E17: 2025-01-09 | F17: 113 | G17: corporate | H17: B | I17: 255.12 | J17: 10 | K17: no | L17: TRAVEL AGENT
A18: 100026 | B18: RESORT HOTEL | C18: ETHAN DAVIS | D18: Spain | E18: 06/03/2025 | F18: 100 | G18: Online TA | H18: A | I18: $306.90 | J18: 4 | K18: No | L18: Corporate Portal
A19: 100034 | B19: resort hotel | C19: Emma Johnson | D19: SPAIN | E19: 9213 | F19: 11 | G19: offline ta/to | H19: B | I19: 105.19 | J19: 2 | K19: yes | L19: Travel Agent
A20: 100035 | B20: Resort Hotel | C20: James Anderson | D20: united kingdom | E20: 2025-05-08 | F20: 83 | G20: offline ta/to | H20: C | I20: $274.92 | J20: 2 | K20: TRUE | L20: DIRECT WEBSITE
A21: 100016 | B21: Resort Hotel | C21: ETHAN DAVIS | D21: Spain | E21: 06/08/2025 | F21: 86 | G21: ONLINE TA | H21: C | I21: 262.83 | J21: 7 | K21: FALSE | L21: Expedia
A22: 100033 | B22: Resort Hotel | C22: Amelia Martin | D22: Portugal | E22: 2025-02-05 | F22: 104 | G22: Groups | H22: C | I22: 82.15 | J22: 4 | K22: yes | L22: TRAVEL AGENT
A23: 100004 | B23: Resort Hotel | C23: mia wilson | D23: portugal | E23: 9190 | F23: 5 | G23: direct | H23: D | I23: $129.61 | J23: 4 | K23: 0 | L23: Corporate Portal
A24: 100011 | B24: City Hotel | C24: emma johnson | D24: IRELAND | E24: 01/06/2025 | F24: 49 | G24: ONLINE TA | H24: D | J24: 8 | K24: FALSE | L24: Corporate Portal
A25: 100021 | B25: RESORT HOTEL | C25: Benjamin Jackson | D25: USA | E25: 9147 | F25: 54 | G25: GROUPS | H25: B | I25: 246.77 | J25: 7 | K25: FALSE | L25: EXPEDIA
A26: 100013 | B26: Resort Hotel | C26: Lucas Garcia | D26: brazil | E26: 03/25/2025 | F26: 120 | G26: online ta | H26: A | I26: 179.15 | J26: 10 | K26: 0 | L26: Booking.com
A27: 100004 | B27: Resort Hotel | C27: mia wilson | D27: portugal | E27: 9190 | F27: 5 | G27: direct | H27: D | I27: $129.61 | J27: 4 | K27: 0 | L27: Corporate Portal
A28: 100009 | B28: Resort Hotel | C28: Mia Wilson | D28: UNITED KINGDOM | E28: 2025-05-08 | F28: 36 | G28: corporate | H28: B | I28: 200.2 | J28: 10 | K28: No | L28: EXPEDIA
A29: 100032 | B29: RESORT HOTEL | C29: HENRY HARRIS | D29: france | E29: 2025-03-02 | F29: 7 | G29: groups | H29: C | I29: 241.33 | J29: 3 | K29: No | L29: travel agent
A30: 100038 | B30: RESORT HOTEL | C30: Henry Harris | D30: brazil | E30: 9224 | F30: -25 | G30: Groups | H30: C | I30: 221.88 | J30: 8 | K30: NO | L30: booking.com
A31: 100046 | B31: RESORT HOTEL | C31: alexander thompson | D31: Germany | E31: 06/25/2025 | F31: 93 | G31: OFFLINE TA/TO | H31: A | I31: 294.88 | J31: 1 | K31: 0 | L31: Travel Agent
A32: 100012 | B32: RESORT HOTEL | C32: Maria Silva | D32: netherlands | E32: 2025-01-28 | F32: 24 | G32: Online TA | H32: E | I32: $77.67 | J32: 4 | K32: NO | L32: corporate portal
A33: 100044 | B33: RESORT HOTEL | C33: noah williams | D33: Brazil | E33: 2025-06-09 | F33: 59 | G33: direct | H33: A | I33: 293.72 | J33: 8 | K33: FALSE | L33: Corporate Portal
A34: 100045 | B34: Resort Hotel | C34: Noah Williams | D34: Ireland | E34: 9264 | F34: 74 | G34: Direct | H34: C | I34: 65.7 | J34: 7 | K34: 1 | L34: CORPORATE PORTAL
A35: 100019 | B35: Resort Hotel | C35: MIA WILSON | D35: usa | E35: 9213 | F35: -109 | G35: Online TA | H35: C | I35: 191.85 | J35: 7 | K35: 0 | L35: direct website
A36: 100001 | B36: RESORT HOTEL | C36: John Smith | E36: 02/08/2025 | F36: 18 | G36: Online TA | H36: E | I36: $82.60 | J36: 7 | K36: Yes | L36: Booking.com
A37: 100040 | B37: City Hotel | C37: james anderson | D37: italy | E37: 9261 | F37: 106 | G37: Online TA | H37: C | I37: 248.77 | J37: 10 | K37: NO | L37: Travel Agent
A38: 100006 | B38: Resort Hotel | C38: Henry Harris | D38: GERMANY | E38: 2025-06-11 | F38: 15 | G38: Direct | H38: D | I38: $101.12 | J38: 1 | K38: NO | L38: Direct Website
A39: 100024 | B39: Resort Hotel | C39: Amelia Martin | D39: ireland | E39: 2025-04-01 | F39: 46 | G39: Direct | H39: D | I39: 281.9 | J39: 7 | K39: FALSE | L39: Corporate Portal
A40: 100036 | B40: Resort Hotel | C40: James Anderson | D40: ITALY | E40: 9261 | F40: 4 | G40: Online TA | H40: B | I40: 310.1 | J40: 10 | K40: no | L40: booking.com
...

Sheet Cleaning Formulas
A1: Booking ID | B1: Hotel | C1: Customer_Name | D1: Country | E1: Arrival Date | F1: Lead_Time Days | G1: Market Segment | H1: ADR | I1: Is Canceled | J1: Duplicate Flag
A2: =Raw_Data!A2 -> 100027 | B2: =PROPER(TRIM(Raw_Data!B2)) -> Resort Hotel | C2: =PROPER(TRIM(Raw_Data!C2)) -> Lucas Garcia | D2: =IF(TRIM(Raw_Data!D2)="","Unknown",PROPER(TRIM(Raw_Data!D2))) -> United Kingdom | E2: =IFERROR(DATEVALUE(Raw_Data!E2),IFERROR(DATE(VALUE(RIGHT(Raw_Data!E2,4)),VALUE(LEFT(Raw_Data!E2,2)),VALUE(MID(Raw_Data!E2,4,2))),"Check Format")) -> 2688402 | F2: =IF(ISNUMBER(Raw_Data!F2),IF(Raw_Data!F2<0,"Invalid (negative)",Raw_Data!F2),"Invalid (non-numeric)") -> 119 | G2: =PROPER(TRIM(Raw_Data!G2)) -> Direct | H2: =IFERROR(VALUE(SUBSTITUTE(SUBSTITUTE(Raw_Data!I2,"$",""),",","")),"Missing/Invalid") -> Missing/Invalid | I2: =IF(OR(UPPER(TRIM(Raw_Data!K2))="YES",UPPER(TRIM(Raw_Data!K2))="TRUE",TRIM(Raw_Data!K2)="1"),"Yes","No") -> No | J2: =IF(COUNTIF($A$2:A2,A2)>1,"Duplicate - Remove","Unique") -> Unique
A3: =Raw_Data!A3 -> 100025 | B3: =PROPER(TRIM(Raw_Data!B3)) -> Resort Hotel | C3: =PROPER(TRIM(Raw_Data!C3)) -> Ava Martinez | D3: =IF(TRIM(Raw_Data!D3)="","Unknown",PROPER(TRIM(Raw_Data!D3))) -> Usa | E3: =IFERROR(DATEVALUE(Raw_Data!E3),IFERROR(DATE(VALUE(RIGHT(Raw_Data!E3,4)),VALUE(LEFT(Raw_Data!E3,2)),VALUE(MID(Raw_Data!E3,4,2))),"Check Format")) -> 45799 | F3: =IF(ISNUMBER(Raw_Data!F3),IF(Raw_Data!F3<0,"Invalid (negative)",Raw_Data!F3),"Invalid (non-numeric)") -> 4 | G3: =PROPER(TRIM(Raw_Data!G3)) -> Online Ta | H3: =IFERROR(VALUE(SUBSTITUTE(SUBSTITUTE(Raw_Data!I3,"$",""),",","")),"Missing/Invalid") -> 95.28 | I3: =IF(OR(UPPER(TRIM(Raw_Data!K3))="YES",UPPER(TRIM(Raw_Data!K3))="TRUE",TRIM(Raw_Data!K3)="1"),"Yes","No") -> Yes | J3: =IF(COUNTIF($A$2:A3,A3)>1,"Duplicate - Remove","Unique") -> Unique
A4: =Raw_Data!A4 -> 100037 | B4: =PROPER(TRIM(Raw_Data!B4)) -> City Hotel | C4: =PROPER(TRIM(Raw_Data!C4)) -> Anna Muller | D4: =IF(TRIM(Raw_Data!D4)="","Unknown",PROPER(TRIM(Raw_Data!D4))) -> Brazil | E4: =IFERROR(DATEVALUE(Raw_Data!E4),IFERROR(DATE(VALUE(RIGHT(Raw_Data!E4,4)),VALUE(LEFT(Raw_Data!E4,2)),VALUE(MID(Raw_Data!E4,4,2))),"Check Format")) -> 45730 | F4: =IF(ISNUMBER(Raw_Data!F4),IF(Raw_Data!F4<0,"Invalid (negative)",Raw_Data!F4),"Invalid (non-numeric)") -> 43 | G4: =PROPER(TRIM(Raw_Data!G4)) -> Direct | H4: =IFERROR(VALUE(SUBSTITUTE(SUBSTITUTE(Raw_Data!I4,"$",""),",","")),"Missing/Invalid") -> 283.01 | I4: =IF(OR(UPPER(TRIM(Raw_Data!K4))="YES",UPPER(TRIM(Raw_Data!K4))="TRUE",TRIM(Raw_Data!K4)="1"),"Yes","No") -> No | J4: =IF(COUNTIF($A$2:A4,A4)>1,"Duplicate - Remove","Unique") -> Unique
A5: =Raw_Data!A5 -> 100028 | B5: =PROPER(TRIM(Raw_Data!B5)) -> City Hotel | C5: =PROPER(TRIM(Raw_Data!C5)) -> Ethan Davis | D5: =IF(TRIM(Raw_Data!D5)="","Unknown",PROPER(TRIM(Raw_Data!D5))) -> United Kingdom | E5: =IFERROR(DATEVALUE(Raw_Data!E5),IFERROR(DATE(VALUE(RIGHT(Raw_Data!E5,4)),VALUE(LEFT(Raw_Data!E5,2)),VALUE(MID(Raw_Data!E5,4,2))),"Check Format")) -> 2695707 | F5: =IF(ISNUMBER(Raw_Data!F5),IF(Raw_Data!F5<0,"Invalid (negative)",Raw_Data!F5),"Invalid (non-numeric)") -> 44 | G5: =PROPER(TRIM(Raw_Data!G5)) -> Online Ta | H5: =IFERROR(VALUE(SUBSTITUTE(SUBSTITUTE(Raw_Data!I5,"$",""),",","")),"Missing/Invalid") -> 273.81 | I5: =IF(OR(UPPER(TRIM(Raw_Data!K5))="YES",UPPER(TRIM(Raw_Data!K5))="TRUE",TRIM(Raw_Data!K5)="1"),"Yes","No") -> No | J5: =IF(COUNTIF($A$2:A5,A5)>1,"Duplicate - Remove","Unique") -> Unique
A6: =Raw_Data!A6 -> 100023 | B6: =PROPER(TRIM(Raw_Data!B6)) -> Resort Hotel | C6: =PROPER(TRIM(Raw_Data!C6)) -> Olivia Brown | D6: =IF(TRIM(Raw_Data!D6)="","Unknown",PROPER(TRIM(Raw_Data!D6))) -> Brazil | E6: =IFERROR(DATEVALUE(Raw_Data!E6),IFERROR(DATE(VALUE(RIGHT(Raw_Data!E6,4)),VALUE(LEFT(Raw_Data!E6,2)),VALUE(MID(Raw_Data!E6,4,2))),"Check Format")) -> 45680 | F6: =IF(ISNUMBER(Raw_Data!F6),IF(Raw_Data!F6<0,"Invalid (negative)",Raw_Data!F6),"Invalid (non-numeric)") -> 37 | G6: =PROPER(TRIM(Raw_Data!G6)) -> Offline Ta/To | H6: =IFERROR(VALUE(SUBSTITUTE(SUBSTITUTE(Raw_Data!I6,"$",""),",","")),"Missing/Invalid") -> 147.32 | I6: =IF(OR(UPPER(TRIM(Raw_Data!K6))="YES",UPPER(TRIM(Raw_Data!K6))="TRUE",TRIM(Raw_Data!K6)="1"),"Yes","No") -> Yes | J6: =IF(COUNTIF($A$2:A6,A6)>1,"Duplicate - Remove","Unique") -> Unique
A7: =Raw_Data!A7 -> 100042 | B7: =PROPER(TRIM(Raw_Data!B7)) -> City Hotel | C7: =PROPER(TRIM(Raw_Data!C7)) -> Mia Wilson | D7: =IF(TRIM(Raw_Data!D7)="","Unknown",PROPER(TRIM(Raw_Data!D7))) -> Usa | E7: =IFERROR(DATEVALUE(Raw_Data!E7),IFERROR(DATE(VALUE(RIGHT(Raw_Data!E7,4)),VALUE(LEFT(Raw_Data!E7,2)),VALUE(MID(Raw_Data!E7,4,2))),"Check Format")) -> 45821 | F7: =IF(ISNUMBER(Raw_Data!F7),IF(Raw_Data!F7<0,"Invalid (negative)",Raw_Data!F7),"Invalid (non-numeric)") -> 84 | G7: =PROPER(TRIM(Raw_Data!G7)) -> Online Ta | H7: =IFERROR(VALUE(SUBSTITUTE(SUBSTITUTE(Raw_Data!I7,"$",""),",","")),"Missing/Invalid") -> 281.61 | I7: =IF(OR(UPPER(TRIM(Raw_Data!K7))="YES",UPPER(TRIM(Raw_Data!K7))="TRUE",TRIM(Raw_Data!K7)="1"),"Yes","No") -> No | J7: =IF(COUNTIF($A$2:A7,A7)>1,"Duplicate - Remove","Unique") -> Unique
A8: =Raw_Data!A8 -> 100039 | B8: =PROPER(TRIM(Raw_Data!B8)) -> Resort Hotel | C8: =PROPER(TRIM(Raw_Data!C8)) -> Henry Harris | D8: =IF(TRIM(Raw_Data!D8)="","Unknown",PROPER(TRIM(Raw_Data!D8))) -> Ireland | E8: =IFERROR(DATEVALUE(Raw_Data!E8),IFERROR(DATE(VALUE(RIGHT(Raw_Data!E8,4)),VALUE(LEFT(Raw_Data!E8,2)),VALUE(MID(Raw_Data!E8,4,2))),"Check Format")) -> 45870 | F8: =IF(ISNUMBER(Raw_Data!F8),IF(Raw_Data!F8<0,"Invalid (negative)",Raw_Data!F8),"Invalid (non-numeric)") -> 108 | G8: =PROPER(TRIM(Raw_Data!G8)) -> Online Ta | H8: =IFERROR(VALUE(SUBSTITUTE(SUBSTITUTE(Raw_Data!I8,"$",""),",","")),"Missing/Invalid") -> 306.24 | I8: =IF(OR(UPPER(TRIM(Raw_Data!K8))="YES",UPPER(TRIM(Raw_Data!K8))="TRUE",TRIM(Raw_Data!K8)="1"),"Yes","No") -> No | J8: =IF(COUNTIF($A$2:A8,A8)>1,"Duplicate - Remove","Unique") -> Unique
A9: =Raw_Data!A9 -> 100003 | B9: =PROPER(TRIM(Raw_Data!B9)) -> Resort Hotel | C9: =PROPER(TRIM(Raw_Data!C9)) -> Maria Silva | D9: =IF(TRIM(Raw_Data!D9)="","Unknown",PROPER(TRIM(Raw_Data!D9))) -> Spain | E9: =IFERROR(DATEVALUE(Raw_Data!E9),IFERROR(DATE(VALUE(RIGHT(Raw_Data!E9,4)),VALUE(LEFT(Raw_Data!E9,2)),VALUE(MID(Raw_Data!E9,4,2))),"Check Format")) -> 2666822 | F9: =IF(ISNUMBER(Raw_Data!F9),IF(Raw_Data!F9<0,"Invalid (negative)",Raw_Data!F9),"Invalid (non-numeric)") -> Invalid (non-numeric) | G9: =PROPER(TRIM(Raw_Data!G9)) -> Offline Ta/To | H9: =IFERROR(VALUE(SUBSTITUTE(SUBSTITUTE(Raw_Data!I9,"$",""),",","")),"Missing/Invalid") -> 158.83 | I9: =IF(OR(UPPER(TRIM(Raw_Data!K9))="YES",UPPER(TRIM(Raw_Data!K9))="TRUE",TRIM(Raw_Data!K9)="1"),"Yes","No") -> No | J9: =IF(COUNTIF($A$2:A9,A9)>1,"Duplicate - Remove","Unique") -> Unique
A10: =Raw_Data!A10 -> 100014 | B10: =PROPER(TRIM(Raw_Data!B10)) -> Resort Hotel | C10: =PROPER(TRIM(Raw_Data!C10)) -> Henry Harris | D10: =IF(TRIM(Raw_Data!D10)="","Unknown",PROPER(TRIM(Raw_Data!D10))) -> Germany | E10: =IFERROR(DATEVALUE(Raw_Data!E10),IFERROR(DATE(VALUE(RIGHT(Raw_Data!E10,4)),VALUE(LEFT(Raw_Data!E10,2)),VALUE(MID(Raw_Data!E10,4,2))),"Check Format")) -> 45812 | F10: =IF(ISNUMBER(Raw_Data!F10),IF(Raw_Data!F10<0,"Invalid (negative)",Raw_Data!F10),"Invalid (non-numeric)") -> 113 | G10: =PROPER(TRIM(Raw_Data!G10)) -> Offline Ta/To | H10: =IFERROR(VALUE(SUBSTITUTE(SUBSTITUTE(Raw_Data!I10,"$",""),",","")),"Missing/Invalid") -> 90.01 | I10: =IF(OR(UPPER(TRIM(Raw_Data!K10))="YES",UPPER(TRIM(Raw_Data!K10))="TRUE",TRIM(Raw_Data!K10)="1"),"Yes","No") -> No | J10: =IF(COUNTIF($A$2:A10,A10)>1,"Duplicate - Remove","Unique") -> Unique
A11: =Raw_Data!A11 -> 100007 | B11: =PROPER(TRIM(Raw_Data!B11)) -> Resort Hotel | C11: =PROPER(TRIM(Raw_Data!C11)) -> Alexander Thompson | D11: =IF(TRIM(Raw_Data!D11)="","Unknown",PROPER(TRIM(Raw_Data!D11))) -> Unknown | E11: =IFERROR(DATEVALUE(Raw_Data!E11),IFERROR(DATE(VALUE(RIGHT(Raw_Data!E11,4)),VALUE(LEFT(Raw_Data!E11,2)),VALUE(MID(Raw_Data!E11,4,2))),"Check Format")) -> 2677444 | F11: =IF(ISNUMBER(Raw_Data!F11),IF(Raw_Data!F11<0,"Invalid (negative)",Raw_Data!F11),"Invalid (non-numeric)") -> 15 | G11: =PROPER(TRIM(Raw_Data!G11)) -> Direct | H11: =IFERROR(VALUE(SUBSTITUTE(SUBSTITUTE(Raw_Data!I11,"$",""),",","")),"Missing/Invalid") -> 122.26 | I11: =IF(OR(UPPER(TRIM(Raw_Data!K11))="YES",UPPER(TRIM(Raw_Data!K11))="TRUE",TRIM(Raw_Data!K11)="1"),"Yes","No") -> No | J11: =IF(COUNTIF($A$2:A11,A11)>1,"Duplicate - Remove","Unique") -> Unique
A12: =Raw_Data!A12 -> 100043 | B12: =PROPER(TRIM(Raw_Data!B12)) -> Resort Hotel | C12: =PROPER(TRIM(Raw_Data!C12)) -> Liam O'Brien | D12: =IF(TRIM(Raw_Data!D12)="","Unknown",PROPER(TRIM(Raw_Data!D12))) -> Brazil | E12: =IFERROR(DATEVALUE(Raw_Data!E12),IFERROR(DATE(VALUE(RIGHT(Raw_Data!E12,4)),VALUE(LEFT(Raw_Data!E12,2)),VALUE(MID(Raw_Data!E12,4,2))),"Check Format")) -> 45711 | F12: =IF(ISNUMBER(Raw_Data!F12),IF(Raw_Data!F12<0,"Invalid (negative)",Raw_Data!F12),"Invalid (non-numeric)") -> Invalid (negative) | G12: =PROPER(TRIM(Raw_Data!G12)) -> Online Ta | H12: =IFERROR(VALUE(SUBSTITUTE(SUBSTITUTE(Raw_Data!I12,"$",""),",","")),"Missing/Invalid") -> Missing/Invalid | I12: =IF(OR(UPPER(TRIM(Raw_Data!K12))="YES",UPPER(TRIM(Raw_Data!K12))="TRUE",TRIM(Raw_Data!K12)="1"),"Yes","No") -> No | J12: =IF(COUNTIF($A$2:A12,A12)>1,"Duplicate - Remove","Unique") -> Unique
A13: =Raw_Data!A13 -> 100020 | B13: =PROPER(TRIM(Raw_Data!B13)) -> City Hotel | C13: =PROPER(TRIM(Raw_Data!C13)) -> Amelia Martin | D13: =IF(TRIM(Raw_Data!D13)="","Unknown",PROPER(TRIM(Raw_Data!D13))) -> Usa | E13: =IFERROR(DATEVALUE(Raw_Data!E13),IFERROR(DATE(VALUE(RIGHT(Raw_Data!E13,4)),VALUE(LEFT(Raw_Data!E13,2)),VALUE(MID(Raw_Data!E13,4,2))),"Check Format")) -> 45967 | F13: =IF(ISNUMBER(Raw_Data!F13),IF(Raw_Data!F13<0,"Invalid (negative)",Raw_Data!F13),"Invalid (non-numeric)") -> 60 | G13: =PROPER(TRIM(Raw_Data!G13)) -> Corporate | H13: =IFERROR(VALUE(SUBSTITUTE(SUBSTITUTE(Raw_Data!I13,"$",""),",","")),"Missing/Invalid") -> Missing/Invalid | I13: =IF(OR(UPPER(TRIM(Raw_Data!K13))="YES",UPPER(TRIM(Raw_Data!K13))="TRUE",TRIM(Raw_Data!K13)="1"),"Yes","No") -> No | J13: =IF(COUNTIF($A$2:A13,A13)>1,"Duplicate - Remove","Unique") -> Unique
... A52: =Raw_Data!A52 -> 100018 | B52: =PROPER(TRIM(Raw_Data!B52)) -> Resort Hotel | C52: =PROPER(TRIM(Raw_Data!C52)) -> Liam O'Brien | D52: =IF(TRIM(Raw_Data!D52)="","Unknown",PROPER(TRIM(Raw_Data!D52))) -> Germany | E52: =IFERROR(DATEVALUE(Raw_Data!E52),IFERROR(DATE(VALUE(RIGHT(Raw_Data!E52,4)),VALUE(LEFT(Raw_Data!E52,2)),VALUE(MID(Raw_Data!E52,4,2))),"Check Format")) -> 45707 | F52: =IF(ISNUMBER(Raw_Data!F52),IF(Raw_Data!F52<0,"Invalid (negative)",Raw_Data!F52),"Invalid (non-numeric)") -> Invalid (non-numeric) | G52: =PROPER(TRIM(Raw_Data!G52)) -> Online Ta | H52: =IFERROR(VALUE(SUBSTITUTE(SUBSTITUTE(Raw_Data!I52,"$",""),",","")),"Missing/Invalid") -> 215.11 | I52: =IF(OR(UPPER(TRIM(Raw_Data!K52))="YES",UPPER(TRIM(Raw_Data!K52))="TRUE",TRIM(Raw_Data!K52)="1"),"Yes","No") -> No | J52: =IF(COUNTIF($A$2:A52,A52)>1,"Duplicate - Remove","Unique") -> Unique

Sheet Clean_Data
A1: Booking ID | B1: Hotel | C1: Customer_Name | D1: Country | E1: Arrival Date | F1: Lead_Time Days | G1: Market Segment | H1: Room Type | I1: ADR | J1: Total Nights | K1: Is Canceled | L1: Booking Channel | M1: Revenue (ADR x Nights)
A2: 100001 | B2: Resort Hotel | C2: John Smith | D2: Unknown | E2: 45696 | F2: 18 | G2: Online Ta | H2: E | I2: 82.6 | J2: 7 | K2: Yes | L2: Booking.Com | M2: =I2*J2 -> 578.2
A3: 100002 | B3: Resort Hotel | C3: James Anderson | D3: Italy | E3: 45721 | F3: 28 | G3: Direct | H3: A | I3: 84.11 | J3: 2 | K3: No | L3: Direct Website | M3: =I3*J3 -> 168.22
A4: 100003 | B4: Resort Hotel | C4: Maria Silva | D4: Spain | E4: 45719 | F4: 49 | G4: Offline Ta/To | H4: A | I4: 158.83 | J4: 8 | K4: No | L4: Direct Website | M4: =I4*J4 -> 1270.64
A5: 100004 | B5: Resort Hotel | C5: Mia Wilson | D5: Portugal | E5: 45715 | F5: 5 | G5: Direct | H5: D | I5: 129.61 | J5: 4 | K5: No | L5: Corporate Portal | M5: =I5*J5 -> 518.44
A6: 100005 | B6: City Hotel | C6: Amelia Martin | D6: Ireland | E6: 45724 | F6: 18 | G6: Groups | H6: D | I6: 83.64 | J6: 1 | K6: No | L6: Expedia | M6: =I6*J6 -> 83.64
A7: 100006 | B7: Resort Hotel | C7: Henry Harris | D7: Germany | E7: 45819 | F7: 15 | G7: Direct | H7: D | I7: 101.12 | J7: 1 | K7: No | L7: Direct Website | M7: =I7*J7 -> 101.12
A8: 100007 | B8: Resort Hotel | C8: Alexander Thompson | D8: Unknown | E8: 45748 | F8: 15 | G8: Direct | H8: C | I8: 122.26 | J8: 4 | K8: No | L8: Booking.Com | M8: =I8*J8 -> 489.04
A9: 100008 | B9: City Hotel | C9: Emma Johnson | D9: Unknown | E9: 45831 | F9: 26 | G9: Direct | H9: D | I9: 200.2 | J9: 6 | K9: No | L9: Corporate Portal | M9: =I9*J9 -> 1201.2
A10: 100009 | B10: Resort Hotel | C10: Mia Wilson | D10: United Kingdom | E10: 45785 | F10: 36 | G10: Corporate | H10: B | I10: 200.2 | J10: 10 | K10: No | L10: Expedia | M10: =I10*J10 -> 2002
A11: 100010 | B11: City Hotel | C11: Liam O'Brien | D11: Spain | E11: 45695 | F11: 69 | G11: Corporate | H11: B | I11: 169.69 | J11: 5 | K11: No | L11: Booking.Com | M11: =I11*J11 -> 848.45
A12: 100011 | B12: City Hotel | C12: Emma Johnson | D12: Ireland | E12: 45663 | F12: 49 | G12: Online Ta | H12: D | I12: 200.2 | J12: 8 | K12: No | L12: Corporate Portal | M12: =I12*J12 -> 1601.6
A13: 100012 | B13: Resort Hotel | C13: Maria Silva | D13: Netherlands | E13: 45685 | F13: 24 | G13: Online Ta | H13: E | I13: 77.67 | J13: 4 | K13: No | L13: Corporate Portal | M13: =I13*J13 -> 310.68
... A47: 100046 | B47: Resort Hotel | C47: Alexander Thompson | D47: Germany | E47: 45833 | F47: 93 | G47: Offline Ta/To | H47: A | I47: 294.88 | J47: 1 | K47: No | L47: Travel Agent | M47: =I47*J47 -> 294.88

Sheet Summary Analysis
A1: Summary Analysis | B1: Amount
A2: Total Clean Records | B2: =COUNTA(Clean_Data!A2:A47) -> 46
A3: Total Cancelled Bookings | B3: =COUNTIF(Clean_Data!K2:K47, "Yes") -> 7
A4: Cancellation Rate | B4: =COUNTIF(Clean_Data!K2:K47, "Yes")/COUNTA(Clean_Data!A2:A47) -> 0.15217391
A5: Total Revenue (Resort Hotel) | B5: =SUMIFS(Clean_Data!M2:M47,Clean_Data!B2:B47,"Resort Hotel") -> 36391.68
A6: Total Revenue (City Hotel) | B6: =SUMIFS(Clean_Data!M2:M47,Clean_Data!B2:B47,"City Hotel") -> 17977.28
A7: Avg ADR - Direct Segment | B7: =AVERAGEIFS(Clean_Data!I2:I47,Clean_Data!G2:G47,"Direct") -> 178.36636
A8: Bookings via Booking.Com | B8: =COUNTIFS(Clean_Data!L2:L47,"Booking.Com") -> 8
